{
 "cells": [
  {
   "cell_type": "code",
   "execution_count": 1,
   "metadata": {
    "collapsed": true
   },
   "outputs": [],
   "source": [
    "import pickle\n",
    "import numpy as np\n",
    "import os\n",
    "import tensorflow as tf"
   ]
  },
  {
   "cell_type": "code",
   "execution_count": 2,
   "metadata": {},
   "outputs": [],
   "source": [
    "meta_file = '/home/pexea12/repos/face/face-research/data/20170512-110547/model-20170512-110547.meta'\n",
    "ckpt_file = '/home/pexea12/repos/face/face-research/data/20170512-110547/model-20170512-110547.ckpt-250000.index'"
   ]
  },
  {
   "cell_type": "code",
   "execution_count": 3,
   "metadata": {},
   "outputs": [
    {
     "name": "stdout",
     "output_type": "stream",
     "text": [
      "WARNING:tensorflow:The saved meta_graph is possibly from an older release:\n",
      "'model_variables' collection should be of type 'byte_list', but instead is of type 'node_list'.\n"
     ]
    }
   ],
   "source": [
    "saver = tf.train.import_meta_graph(meta_file)"
   ]
  },
  {
   "cell_type": "code",
   "execution_count": 9,
   "metadata": {},
   "outputs": [],
   "source": [
    "sess = tf.Session()"
   ]
  },
  {
   "cell_type": "code",
   "execution_count": 11,
   "metadata": {},
   "outputs": [
    {
     "name": "stdout",
     "output_type": "stream",
     "text": [
      "INFO:tensorflow:Restoring parameters from /home/pexea12/repos/face/face-research/data/20170512-110547/model-20170512-110547.ckpt-250000.index\n"
     ]
    },
    {
     "ename": "NotFoundError",
     "evalue": "Tensor name \"Logits/weights\" not found in checkpoint files /home/pexea12/repos/face/face-research/data/20170512-110547/model-20170512-110547.ckpt-250000.index\n\t [[Node: save/RestoreV2_491 = RestoreV2[dtypes=[DT_FLOAT], _device=\"/job:localhost/replica:0/task:0/cpu:0\"](_arg_save/Const_0_0, save/RestoreV2_491/tensor_names, save/RestoreV2_491/shape_and_slices)]]\n\t [[Node: save/RestoreV2_490/_1 = _Recv[client_terminated=false, recv_device=\"/job:localhost/replica:0/task:0/gpu:0\", send_device=\"/job:localhost/replica:0/task:0/cpu:0\", send_device_incarnation=1, tensor_name=\"edge_988_save/RestoreV2_490\", tensor_type=DT_FLOAT, _device=\"/job:localhost/replica:0/task:0/gpu:0\"]()]]\n\nCaused by op 'save/RestoreV2_491', defined at:\n  File \"/usr/lib/python3.6/runpy.py\", line 193, in _run_module_as_main\n    \"__main__\", mod_spec)\n  File \"/usr/lib/python3.6/runpy.py\", line 85, in _run_code\n    exec(code, run_globals)\n  File \"/usr/lib/python3.6/site-packages/ipykernel/__main__.py\", line 3, in <module>\n    app.launch_new_instance()\n  File \"/usr/lib/python3.6/site-packages/traitlets/config/application.py\", line 658, in launch_instance\n    app.start()\n  File \"/usr/lib/python3.6/site-packages/ipykernel/kernelapp.py\", line 474, in start\n    ioloop.IOLoop.instance().start()\n  File \"/usr/lib/python3.6/site-packages/zmq/eventloop/ioloop.py\", line 177, in start\n    super(ZMQIOLoop, self).start()\n  File \"/usr/lib/python3.6/site-packages/tornado/ioloop.py\", line 888, in start\n    handler_func(fd_obj, events)\n  File \"/usr/lib/python3.6/site-packages/tornado/stack_context.py\", line 277, in null_wrapper\n    return fn(*args, **kwargs)\n  File \"/usr/lib/python3.6/site-packages/zmq/eventloop/zmqstream.py\", line 440, in _handle_events\n    self._handle_recv()\n  File \"/usr/lib/python3.6/site-packages/zmq/eventloop/zmqstream.py\", line 472, in _handle_recv\n    self._run_callback(callback, msg)\n  File \"/usr/lib/python3.6/site-packages/zmq/eventloop/zmqstream.py\", line 414, in _run_callback\n    callback(*args, **kwargs)\n  File \"/usr/lib/python3.6/site-packages/tornado/stack_context.py\", line 277, in null_wrapper\n    return fn(*args, **kwargs)\n  File \"/usr/lib/python3.6/site-packages/ipykernel/kernelbase.py\", line 276, in dispatcher\n    return self.dispatch_shell(stream, msg)\n  File \"/usr/lib/python3.6/site-packages/ipykernel/kernelbase.py\", line 228, in dispatch_shell\n    handler(stream, idents, msg)\n  File \"/usr/lib/python3.6/site-packages/ipykernel/kernelbase.py\", line 390, in execute_request\n    user_expressions, allow_stdin)\n  File \"/usr/lib/python3.6/site-packages/ipykernel/ipkernel.py\", line 196, in do_execute\n    res = shell.run_cell(code, store_history=store_history, silent=silent)\n  File \"/usr/lib/python3.6/site-packages/ipykernel/zmqshell.py\", line 501, in run_cell\n    return super(ZMQInteractiveShell, self).run_cell(*args, **kwargs)\n  File \"/usr/lib/python3.6/site-packages/IPython/core/interactiveshell.py\", line 2717, in run_cell\n    interactivity=interactivity, compiler=compiler, result=result)\n  File \"/usr/lib/python3.6/site-packages/IPython/core/interactiveshell.py\", line 2821, in run_ast_nodes\n    if self.run_code(code, result):\n  File \"/usr/lib/python3.6/site-packages/IPython/core/interactiveshell.py\", line 2881, in run_code\n    exec(code_obj, self.user_global_ns, self.user_ns)\n  File \"<ipython-input-3-071f77872099>\", line 1, in <module>\n    saver = tf.train.import_meta_graph(meta_file)\n  File \"/usr/lib/python3.6/site-packages/tensorflow/python/training/saver.py\", line 1698, in import_meta_graph\n    **kwargs)\n  File \"/usr/lib/python3.6/site-packages/tensorflow/python/framework/meta_graph.py\", line 656, in import_scoped_meta_graph\n    producer_op_list=producer_op_list)\n  File \"/usr/lib/python3.6/site-packages/tensorflow/python/framework/importer.py\", line 313, in import_graph_def\n    op_def=op_def)\n  File \"/usr/lib/python3.6/site-packages/tensorflow/python/framework/ops.py\", line 2630, in create_op\n    original_op=self._default_original_op, op_def=op_def)\n  File \"/usr/lib/python3.6/site-packages/tensorflow/python/framework/ops.py\", line 1204, in __init__\n    self._traceback = self._graph._extract_stack()  # pylint: disable=protected-access\n\nNotFoundError (see above for traceback): Tensor name \"Logits/weights\" not found in checkpoint files /home/pexea12/repos/face/face-research/data/20170512-110547/model-20170512-110547.ckpt-250000.index\n\t [[Node: save/RestoreV2_491 = RestoreV2[dtypes=[DT_FLOAT], _device=\"/job:localhost/replica:0/task:0/cpu:0\"](_arg_save/Const_0_0, save/RestoreV2_491/tensor_names, save/RestoreV2_491/shape_and_slices)]]\n\t [[Node: save/RestoreV2_490/_1 = _Recv[client_terminated=false, recv_device=\"/job:localhost/replica:0/task:0/gpu:0\", send_device=\"/job:localhost/replica:0/task:0/cpu:0\", send_device_incarnation=1, tensor_name=\"edge_988_save/RestoreV2_490\", tensor_type=DT_FLOAT, _device=\"/job:localhost/replica:0/task:0/gpu:0\"]()]]\n",
     "output_type": "error",
     "traceback": [
      "\u001b[0;31m---------------------------------------------------------------------------\u001b[0m",
      "\u001b[0;31mNotFoundError\u001b[0m                             Traceback (most recent call last)",
      "\u001b[0;32m/usr/lib/python3.6/site-packages/tensorflow/python/client/session.py\u001b[0m in \u001b[0;36m_do_call\u001b[0;34m(self, fn, *args)\u001b[0m\n\u001b[1;32m   1326\u001b[0m     \u001b[0;32mtry\u001b[0m\u001b[0;34m:\u001b[0m\u001b[0;34m\u001b[0m\u001b[0m\n\u001b[0;32m-> 1327\u001b[0;31m       \u001b[0;32mreturn\u001b[0m \u001b[0mfn\u001b[0m\u001b[0;34m(\u001b[0m\u001b[0;34m*\u001b[0m\u001b[0margs\u001b[0m\u001b[0;34m)\u001b[0m\u001b[0;34m\u001b[0m\u001b[0m\n\u001b[0m\u001b[1;32m   1328\u001b[0m     \u001b[0;32mexcept\u001b[0m \u001b[0merrors\u001b[0m\u001b[0;34m.\u001b[0m\u001b[0mOpError\u001b[0m \u001b[0;32mas\u001b[0m \u001b[0me\u001b[0m\u001b[0;34m:\u001b[0m\u001b[0;34m\u001b[0m\u001b[0m\n",
      "\u001b[0;32m/usr/lib/python3.6/site-packages/tensorflow/python/client/session.py\u001b[0m in \u001b[0;36m_run_fn\u001b[0;34m(session, feed_dict, fetch_list, target_list, options, run_metadata)\u001b[0m\n\u001b[1;32m   1305\u001b[0m                                    \u001b[0mfeed_dict\u001b[0m\u001b[0;34m,\u001b[0m \u001b[0mfetch_list\u001b[0m\u001b[0;34m,\u001b[0m \u001b[0mtarget_list\u001b[0m\u001b[0;34m,\u001b[0m\u001b[0;34m\u001b[0m\u001b[0m\n\u001b[0;32m-> 1306\u001b[0;31m                                    status, run_metadata)\n\u001b[0m\u001b[1;32m   1307\u001b[0m \u001b[0;34m\u001b[0m\u001b[0m\n",
      "\u001b[0;32m/usr/lib/python3.6/contextlib.py\u001b[0m in \u001b[0;36m__exit__\u001b[0;34m(self, type, value, traceback)\u001b[0m\n\u001b[1;32m     87\u001b[0m             \u001b[0;32mtry\u001b[0m\u001b[0;34m:\u001b[0m\u001b[0;34m\u001b[0m\u001b[0m\n\u001b[0;32m---> 88\u001b[0;31m                 \u001b[0mnext\u001b[0m\u001b[0;34m(\u001b[0m\u001b[0mself\u001b[0m\u001b[0;34m.\u001b[0m\u001b[0mgen\u001b[0m\u001b[0;34m)\u001b[0m\u001b[0;34m\u001b[0m\u001b[0m\n\u001b[0m\u001b[1;32m     89\u001b[0m             \u001b[0;32mexcept\u001b[0m \u001b[0mStopIteration\u001b[0m\u001b[0;34m:\u001b[0m\u001b[0;34m\u001b[0m\u001b[0m\n",
      "\u001b[0;32m/usr/lib/python3.6/site-packages/tensorflow/python/framework/errors_impl.py\u001b[0m in \u001b[0;36mraise_exception_on_not_ok_status\u001b[0;34m()\u001b[0m\n\u001b[1;32m    465\u001b[0m           \u001b[0mcompat\u001b[0m\u001b[0;34m.\u001b[0m\u001b[0mas_text\u001b[0m\u001b[0;34m(\u001b[0m\u001b[0mpywrap_tensorflow\u001b[0m\u001b[0;34m.\u001b[0m\u001b[0mTF_Message\u001b[0m\u001b[0;34m(\u001b[0m\u001b[0mstatus\u001b[0m\u001b[0;34m)\u001b[0m\u001b[0;34m)\u001b[0m\u001b[0;34m,\u001b[0m\u001b[0;34m\u001b[0m\u001b[0m\n\u001b[0;32m--> 466\u001b[0;31m           pywrap_tensorflow.TF_GetCode(status))\n\u001b[0m\u001b[1;32m    467\u001b[0m   \u001b[0;32mfinally\u001b[0m\u001b[0;34m:\u001b[0m\u001b[0;34m\u001b[0m\u001b[0m\n",
      "\u001b[0;31mNotFoundError\u001b[0m: Tensor name \"Logits/weights\" not found in checkpoint files /home/pexea12/repos/face/face-research/data/20170512-110547/model-20170512-110547.ckpt-250000.index\n\t [[Node: save/RestoreV2_491 = RestoreV2[dtypes=[DT_FLOAT], _device=\"/job:localhost/replica:0/task:0/cpu:0\"](_arg_save/Const_0_0, save/RestoreV2_491/tensor_names, save/RestoreV2_491/shape_and_slices)]]\n\t [[Node: save/RestoreV2_490/_1 = _Recv[client_terminated=false, recv_device=\"/job:localhost/replica:0/task:0/gpu:0\", send_device=\"/job:localhost/replica:0/task:0/cpu:0\", send_device_incarnation=1, tensor_name=\"edge_988_save/RestoreV2_490\", tensor_type=DT_FLOAT, _device=\"/job:localhost/replica:0/task:0/gpu:0\"]()]]",
      "\nDuring handling of the above exception, another exception occurred:\n",
      "\u001b[0;31mNotFoundError\u001b[0m                             Traceback (most recent call last)",
      "\u001b[0;32m<ipython-input-11-f19f72323aae>\u001b[0m in \u001b[0;36m<module>\u001b[0;34m()\u001b[0m\n\u001b[0;32m----> 1\u001b[0;31m \u001b[0msaver\u001b[0m\u001b[0;34m.\u001b[0m\u001b[0mrestore\u001b[0m\u001b[0;34m(\u001b[0m\u001b[0msess\u001b[0m\u001b[0;34m,\u001b[0m \u001b[0mckpt_file\u001b[0m\u001b[0;34m)\u001b[0m\u001b[0;34m\u001b[0m\u001b[0m\n\u001b[0m",
      "\u001b[0;32m/usr/lib/python3.6/site-packages/tensorflow/python/training/saver.py\u001b[0m in \u001b[0;36mrestore\u001b[0;34m(self, sess, save_path)\u001b[0m\n\u001b[1;32m   1558\u001b[0m     \u001b[0mlogging\u001b[0m\u001b[0;34m.\u001b[0m\u001b[0minfo\u001b[0m\u001b[0;34m(\u001b[0m\u001b[0;34m\"Restoring parameters from %s\"\u001b[0m\u001b[0;34m,\u001b[0m \u001b[0msave_path\u001b[0m\u001b[0;34m)\u001b[0m\u001b[0;34m\u001b[0m\u001b[0m\n\u001b[1;32m   1559\u001b[0m     sess.run(self.saver_def.restore_op_name,\n\u001b[0;32m-> 1560\u001b[0;31m              {self.saver_def.filename_tensor_name: save_path})\n\u001b[0m\u001b[1;32m   1561\u001b[0m \u001b[0;34m\u001b[0m\u001b[0m\n\u001b[1;32m   1562\u001b[0m   \u001b[0;34m@\u001b[0m\u001b[0mstaticmethod\u001b[0m\u001b[0;34m\u001b[0m\u001b[0m\n",
      "\u001b[0;32m/usr/lib/python3.6/site-packages/tensorflow/python/client/session.py\u001b[0m in \u001b[0;36mrun\u001b[0;34m(self, fetches, feed_dict, options, run_metadata)\u001b[0m\n\u001b[1;32m    893\u001b[0m     \u001b[0;32mtry\u001b[0m\u001b[0;34m:\u001b[0m\u001b[0;34m\u001b[0m\u001b[0m\n\u001b[1;32m    894\u001b[0m       result = self._run(None, fetches, feed_dict, options_ptr,\n\u001b[0;32m--> 895\u001b[0;31m                          run_metadata_ptr)\n\u001b[0m\u001b[1;32m    896\u001b[0m       \u001b[0;32mif\u001b[0m \u001b[0mrun_metadata\u001b[0m\u001b[0;34m:\u001b[0m\u001b[0;34m\u001b[0m\u001b[0m\n\u001b[1;32m    897\u001b[0m         \u001b[0mproto_data\u001b[0m \u001b[0;34m=\u001b[0m \u001b[0mtf_session\u001b[0m\u001b[0;34m.\u001b[0m\u001b[0mTF_GetBuffer\u001b[0m\u001b[0;34m(\u001b[0m\u001b[0mrun_metadata_ptr\u001b[0m\u001b[0;34m)\u001b[0m\u001b[0;34m\u001b[0m\u001b[0m\n",
      "\u001b[0;32m/usr/lib/python3.6/site-packages/tensorflow/python/client/session.py\u001b[0m in \u001b[0;36m_run\u001b[0;34m(self, handle, fetches, feed_dict, options, run_metadata)\u001b[0m\n\u001b[1;32m   1122\u001b[0m     \u001b[0;32mif\u001b[0m \u001b[0mfinal_fetches\u001b[0m \u001b[0;32mor\u001b[0m \u001b[0mfinal_targets\u001b[0m \u001b[0;32mor\u001b[0m \u001b[0;34m(\u001b[0m\u001b[0mhandle\u001b[0m \u001b[0;32mand\u001b[0m \u001b[0mfeed_dict_tensor\u001b[0m\u001b[0;34m)\u001b[0m\u001b[0;34m:\u001b[0m\u001b[0;34m\u001b[0m\u001b[0m\n\u001b[1;32m   1123\u001b[0m       results = self._do_run(handle, final_targets, final_fetches,\n\u001b[0;32m-> 1124\u001b[0;31m                              feed_dict_tensor, options, run_metadata)\n\u001b[0m\u001b[1;32m   1125\u001b[0m     \u001b[0;32melse\u001b[0m\u001b[0;34m:\u001b[0m\u001b[0;34m\u001b[0m\u001b[0m\n\u001b[1;32m   1126\u001b[0m       \u001b[0mresults\u001b[0m \u001b[0;34m=\u001b[0m \u001b[0;34m[\u001b[0m\u001b[0;34m]\u001b[0m\u001b[0;34m\u001b[0m\u001b[0m\n",
      "\u001b[0;32m/usr/lib/python3.6/site-packages/tensorflow/python/client/session.py\u001b[0m in \u001b[0;36m_do_run\u001b[0;34m(self, handle, target_list, fetch_list, feed_dict, options, run_metadata)\u001b[0m\n\u001b[1;32m   1319\u001b[0m     \u001b[0;32mif\u001b[0m \u001b[0mhandle\u001b[0m \u001b[0;32mis\u001b[0m \u001b[0;32mNone\u001b[0m\u001b[0;34m:\u001b[0m\u001b[0;34m\u001b[0m\u001b[0m\n\u001b[1;32m   1320\u001b[0m       return self._do_call(_run_fn, self._session, feeds, fetches, targets,\n\u001b[0;32m-> 1321\u001b[0;31m                            options, run_metadata)\n\u001b[0m\u001b[1;32m   1322\u001b[0m     \u001b[0;32melse\u001b[0m\u001b[0;34m:\u001b[0m\u001b[0;34m\u001b[0m\u001b[0m\n\u001b[1;32m   1323\u001b[0m       \u001b[0;32mreturn\u001b[0m \u001b[0mself\u001b[0m\u001b[0;34m.\u001b[0m\u001b[0m_do_call\u001b[0m\u001b[0;34m(\u001b[0m\u001b[0m_prun_fn\u001b[0m\u001b[0;34m,\u001b[0m \u001b[0mself\u001b[0m\u001b[0;34m.\u001b[0m\u001b[0m_session\u001b[0m\u001b[0;34m,\u001b[0m \u001b[0mhandle\u001b[0m\u001b[0;34m,\u001b[0m \u001b[0mfeeds\u001b[0m\u001b[0;34m,\u001b[0m \u001b[0mfetches\u001b[0m\u001b[0;34m)\u001b[0m\u001b[0;34m\u001b[0m\u001b[0m\n",
      "\u001b[0;32m/usr/lib/python3.6/site-packages/tensorflow/python/client/session.py\u001b[0m in \u001b[0;36m_do_call\u001b[0;34m(self, fn, *args)\u001b[0m\n\u001b[1;32m   1338\u001b[0m         \u001b[0;32mexcept\u001b[0m \u001b[0mKeyError\u001b[0m\u001b[0;34m:\u001b[0m\u001b[0;34m\u001b[0m\u001b[0m\n\u001b[1;32m   1339\u001b[0m           \u001b[0;32mpass\u001b[0m\u001b[0;34m\u001b[0m\u001b[0m\n\u001b[0;32m-> 1340\u001b[0;31m       \u001b[0;32mraise\u001b[0m \u001b[0mtype\u001b[0m\u001b[0;34m(\u001b[0m\u001b[0me\u001b[0m\u001b[0;34m)\u001b[0m\u001b[0;34m(\u001b[0m\u001b[0mnode_def\u001b[0m\u001b[0;34m,\u001b[0m \u001b[0mop\u001b[0m\u001b[0;34m,\u001b[0m \u001b[0mmessage\u001b[0m\u001b[0;34m)\u001b[0m\u001b[0;34m\u001b[0m\u001b[0m\n\u001b[0m\u001b[1;32m   1341\u001b[0m \u001b[0;34m\u001b[0m\u001b[0m\n\u001b[1;32m   1342\u001b[0m   \u001b[0;32mdef\u001b[0m \u001b[0m_extend_graph\u001b[0m\u001b[0;34m(\u001b[0m\u001b[0mself\u001b[0m\u001b[0;34m)\u001b[0m\u001b[0;34m:\u001b[0m\u001b[0;34m\u001b[0m\u001b[0m\n",
      "\u001b[0;31mNotFoundError\u001b[0m: Tensor name \"Logits/weights\" not found in checkpoint files /home/pexea12/repos/face/face-research/data/20170512-110547/model-20170512-110547.ckpt-250000.index\n\t [[Node: save/RestoreV2_491 = RestoreV2[dtypes=[DT_FLOAT], _device=\"/job:localhost/replica:0/task:0/cpu:0\"](_arg_save/Const_0_0, save/RestoreV2_491/tensor_names, save/RestoreV2_491/shape_and_slices)]]\n\t [[Node: save/RestoreV2_490/_1 = _Recv[client_terminated=false, recv_device=\"/job:localhost/replica:0/task:0/gpu:0\", send_device=\"/job:localhost/replica:0/task:0/cpu:0\", send_device_incarnation=1, tensor_name=\"edge_988_save/RestoreV2_490\", tensor_type=DT_FLOAT, _device=\"/job:localhost/replica:0/task:0/gpu:0\"]()]]\n\nCaused by op 'save/RestoreV2_491', defined at:\n  File \"/usr/lib/python3.6/runpy.py\", line 193, in _run_module_as_main\n    \"__main__\", mod_spec)\n  File \"/usr/lib/python3.6/runpy.py\", line 85, in _run_code\n    exec(code, run_globals)\n  File \"/usr/lib/python3.6/site-packages/ipykernel/__main__.py\", line 3, in <module>\n    app.launch_new_instance()\n  File \"/usr/lib/python3.6/site-packages/traitlets/config/application.py\", line 658, in launch_instance\n    app.start()\n  File \"/usr/lib/python3.6/site-packages/ipykernel/kernelapp.py\", line 474, in start\n    ioloop.IOLoop.instance().start()\n  File \"/usr/lib/python3.6/site-packages/zmq/eventloop/ioloop.py\", line 177, in start\n    super(ZMQIOLoop, self).start()\n  File \"/usr/lib/python3.6/site-packages/tornado/ioloop.py\", line 888, in start\n    handler_func(fd_obj, events)\n  File \"/usr/lib/python3.6/site-packages/tornado/stack_context.py\", line 277, in null_wrapper\n    return fn(*args, **kwargs)\n  File \"/usr/lib/python3.6/site-packages/zmq/eventloop/zmqstream.py\", line 440, in _handle_events\n    self._handle_recv()\n  File \"/usr/lib/python3.6/site-packages/zmq/eventloop/zmqstream.py\", line 472, in _handle_recv\n    self._run_callback(callback, msg)\n  File \"/usr/lib/python3.6/site-packages/zmq/eventloop/zmqstream.py\", line 414, in _run_callback\n    callback(*args, **kwargs)\n  File \"/usr/lib/python3.6/site-packages/tornado/stack_context.py\", line 277, in null_wrapper\n    return fn(*args, **kwargs)\n  File \"/usr/lib/python3.6/site-packages/ipykernel/kernelbase.py\", line 276, in dispatcher\n    return self.dispatch_shell(stream, msg)\n  File \"/usr/lib/python3.6/site-packages/ipykernel/kernelbase.py\", line 228, in dispatch_shell\n    handler(stream, idents, msg)\n  File \"/usr/lib/python3.6/site-packages/ipykernel/kernelbase.py\", line 390, in execute_request\n    user_expressions, allow_stdin)\n  File \"/usr/lib/python3.6/site-packages/ipykernel/ipkernel.py\", line 196, in do_execute\n    res = shell.run_cell(code, store_history=store_history, silent=silent)\n  File \"/usr/lib/python3.6/site-packages/ipykernel/zmqshell.py\", line 501, in run_cell\n    return super(ZMQInteractiveShell, self).run_cell(*args, **kwargs)\n  File \"/usr/lib/python3.6/site-packages/IPython/core/interactiveshell.py\", line 2717, in run_cell\n    interactivity=interactivity, compiler=compiler, result=result)\n  File \"/usr/lib/python3.6/site-packages/IPython/core/interactiveshell.py\", line 2821, in run_ast_nodes\n    if self.run_code(code, result):\n  File \"/usr/lib/python3.6/site-packages/IPython/core/interactiveshell.py\", line 2881, in run_code\n    exec(code_obj, self.user_global_ns, self.user_ns)\n  File \"<ipython-input-3-071f77872099>\", line 1, in <module>\n    saver = tf.train.import_meta_graph(meta_file)\n  File \"/usr/lib/python3.6/site-packages/tensorflow/python/training/saver.py\", line 1698, in import_meta_graph\n    **kwargs)\n  File \"/usr/lib/python3.6/site-packages/tensorflow/python/framework/meta_graph.py\", line 656, in import_scoped_meta_graph\n    producer_op_list=producer_op_list)\n  File \"/usr/lib/python3.6/site-packages/tensorflow/python/framework/importer.py\", line 313, in import_graph_def\n    op_def=op_def)\n  File \"/usr/lib/python3.6/site-packages/tensorflow/python/framework/ops.py\", line 2630, in create_op\n    original_op=self._default_original_op, op_def=op_def)\n  File \"/usr/lib/python3.6/site-packages/tensorflow/python/framework/ops.py\", line 1204, in __init__\n    self._traceback = self._graph._extract_stack()  # pylint: disable=protected-access\n\nNotFoundError (see above for traceback): Tensor name \"Logits/weights\" not found in checkpoint files /home/pexea12/repos/face/face-research/data/20170512-110547/model-20170512-110547.ckpt-250000.index\n\t [[Node: save/RestoreV2_491 = RestoreV2[dtypes=[DT_FLOAT], _device=\"/job:localhost/replica:0/task:0/cpu:0\"](_arg_save/Const_0_0, save/RestoreV2_491/tensor_names, save/RestoreV2_491/shape_and_slices)]]\n\t [[Node: save/RestoreV2_490/_1 = _Recv[client_terminated=false, recv_device=\"/job:localhost/replica:0/task:0/gpu:0\", send_device=\"/job:localhost/replica:0/task:0/cpu:0\", send_device_incarnation=1, tensor_name=\"edge_988_save/RestoreV2_490\", tensor_type=DT_FLOAT, _device=\"/job:localhost/replica:0/task:0/gpu:0\"]()]]\n"
     ]
    }
   ],
   "source": [
    "saver.restore(sess, ckpt_file)"
   ]
  },
  {
   "cell_type": "code",
   "execution_count": null,
   "metadata": {
    "collapsed": true
   },
   "outputs": [],
   "source": []
  }
 ],
 "metadata": {
  "kernelspec": {
   "display_name": "Python 3",
   "language": "python",
   "name": "python3"
  },
  "language_info": {
   "codemirror_mode": {
    "name": "ipython",
    "version": 3
   },
   "file_extension": ".py",
   "mimetype": "text/x-python",
   "name": "python",
   "nbconvert_exporter": "python",
   "pygments_lexer": "ipython3",
   "version": "3.6.2"
  }
 },
 "nbformat": 4,
 "nbformat_minor": 2
}
